Traceback (most recent call last):
  File "/Users/luo/miniconda3/envs/venv-pyrsimg/lib/python3.9/site-packages/jupyter_cache/executors/utils.py", line 58, in single_nb_execution
    executenb(
  File "/Users/luo/miniconda3/envs/venv-pyrsimg/lib/python3.9/site-packages/nbclient/client.py", line 1204, in execute
    return NotebookClient(nb=nb, resources=resources, km=km, **kwargs).execute()
  File "/Users/luo/miniconda3/envs/venv-pyrsimg/lib/python3.9/site-packages/nbclient/util.py", line 84, in wrapped
    return just_run(coro(*args, **kwargs))
  File "/Users/luo/miniconda3/envs/venv-pyrsimg/lib/python3.9/site-packages/nbclient/util.py", line 62, in just_run
    return loop.run_until_complete(coro)
  File "/Users/luo/miniconda3/envs/venv-pyrsimg/lib/python3.9/site-packages/nest_asyncio.py", line 90, in run_until_complete
    return f.result()
  File "/Users/luo/miniconda3/envs/venv-pyrsimg/lib/python3.9/asyncio/futures.py", line 201, in result
    raise self._exception
  File "/Users/luo/miniconda3/envs/venv-pyrsimg/lib/python3.9/asyncio/tasks.py", line 256, in __step
    result = coro.send(None)
  File "/Users/luo/miniconda3/envs/venv-pyrsimg/lib/python3.9/site-packages/nbclient/client.py", line 663, in async_execute
    await self.async_execute_cell(
  File "/Users/luo/miniconda3/envs/venv-pyrsimg/lib/python3.9/site-packages/nbclient/client.py", line 965, in async_execute_cell
    await self._check_raise_for_error(cell, cell_index, exec_reply)
  File "/Users/luo/miniconda3/envs/venv-pyrsimg/lib/python3.9/site-packages/nbclient/client.py", line 862, in _check_raise_for_error
    raise CellExecutionError.from_cell_and_msg(cell, exec_reply_content)
nbclient.exceptions.CellExecutionError: An error occurred while executing the following cell:
------------------
path_img = 'docs/source/examples/data/l8_scene_05.tif'
img_ins = readTiff(path_in=path_img)

------------------

[0;31m---------------------------------------------------------------------------[0m
[0;31mAttributeError[0m                            Traceback (most recent call last)
Cell [0;32mIn[2], line 2[0m
[1;32m      1[0m path_img [38;5;241m=[39m [38;5;124m'[39m[38;5;124mdocs/source/examples/data/l8_scene_05.tif[39m[38;5;124m'[39m
[0;32m----> 2[0m img_ins [38;5;241m=[39m [43mreadTiff[49m[43m([49m[43mpath_in[49m[38;5;241;43m=[39;49m[43mpath_img[49m[43m)[49m

File [0;32m~/Library/CloudStorage/OneDrive-Personal/GitHub/pyrsimg/pyrsimg/rsimg_io.py:24[0m, in [0;36mreadTiff.__init__[0;34m(self, path_in)[0m
[1;32m     22[0m [38;5;28;01mdef[39;00m [38;5;21m__init__[39m([38;5;28mself[39m, path_in):
[1;32m     23[0m     RS_Data[38;5;241m=[39mgdal[38;5;241m.[39mOpen(path_in)
[0;32m---> 24[0m     [38;5;28mself[39m[38;5;241m.[39mgeotrans [38;5;241m=[39m [43mRS_Data[49m[38;5;241;43m.[39;49m[43mGetGeoTransform[49m()  [38;5;66;03m# [39;00m
[1;32m     25[0m     [38;5;28mself[39m[38;5;241m.[39mrow [38;5;241m=[39m RS_Data[38;5;241m.[39mRasterYSize
[1;32m     26[0m     [38;5;28mself[39m[38;5;241m.[39mcol [38;5;241m=[39m RS_Data[38;5;241m.[39mRasterXSize  [38;5;66;03m# [39;00m

[0;31mAttributeError[0m: 'NoneType' object has no attribute 'GetGeoTransform'
AttributeError: 'NoneType' object has no attribute 'GetGeoTransform'

