Traceback (most recent call last):
  File "/Users/luo/miniconda3/envs/venv-pyrsimg/lib/python3.9/site-packages/nbclient/client.py", line 730, in _async_poll_for_reply
    msg = await ensure_async(self.kc.shell_channel.get_msg(timeout=new_timeout))
  File "/Users/luo/miniconda3/envs/venv-pyrsimg/lib/python3.9/site-packages/nbclient/util.py", line 96, in ensure_async
    result = await obj
  File "/Users/luo/miniconda3/envs/venv-pyrsimg/lib/python3.9/site-packages/jupyter_client/channels.py", line 315, in get_msg
    raise Empty
_queue.Empty

During handling of the above exception, another exception occurred:

Traceback (most recent call last):
  File "/Users/luo/miniconda3/envs/venv-pyrsimg/lib/python3.9/site-packages/jupyter_cache/executors/utils.py", line 58, in single_nb_execution
    executenb(
  File "/Users/luo/miniconda3/envs/venv-pyrsimg/lib/python3.9/site-packages/nbclient/client.py", line 1204, in execute
    return NotebookClient(nb=nb, resources=resources, km=km, **kwargs).execute()
  File "/Users/luo/miniconda3/envs/venv-pyrsimg/lib/python3.9/site-packages/nbclient/util.py", line 84, in wrapped
    return just_run(coro(*args, **kwargs))
  File "/Users/luo/miniconda3/envs/venv-pyrsimg/lib/python3.9/site-packages/nbclient/util.py", line 62, in just_run
    return loop.run_until_complete(coro)
  File "/Users/luo/miniconda3/envs/venv-pyrsimg/lib/python3.9/site-packages/nest_asyncio.py", line 90, in run_until_complete
    return f.result()
  File "/Users/luo/miniconda3/envs/venv-pyrsimg/lib/python3.9/asyncio/futures.py", line 201, in result
    raise self._exception
  File "/Users/luo/miniconda3/envs/venv-pyrsimg/lib/python3.9/asyncio/tasks.py", line 256, in __step
    result = coro.send(None)
  File "/Users/luo/miniconda3/envs/venv-pyrsimg/lib/python3.9/site-packages/nbclient/client.py", line 663, in async_execute
    await self.async_execute_cell(
  File "/Users/luo/miniconda3/envs/venv-pyrsimg/lib/python3.9/site-packages/nbclient/client.py", line 949, in async_execute_cell
    exec_reply = await self.task_poll_for_reply
  File "/Users/luo/miniconda3/envs/venv-pyrsimg/lib/python3.9/asyncio/futures.py", line 284, in __await__
    yield self  # This tells Task to wait for completion.
  File "/Users/luo/miniconda3/envs/venv-pyrsimg/lib/python3.9/asyncio/tasks.py", line 328, in __wakeup
    future.result()
  File "/Users/luo/miniconda3/envs/venv-pyrsimg/lib/python3.9/asyncio/futures.py", line 201, in result
    raise self._exception
  File "/Users/luo/miniconda3/envs/venv-pyrsimg/lib/python3.9/asyncio/tasks.py", line 256, in __step
    result = coro.send(None)
  File "/Users/luo/miniconda3/envs/venv-pyrsimg/lib/python3.9/site-packages/nbclient/client.py", line 754, in _async_poll_for_reply
    await self._async_handle_timeout(timeout, cell)
  File "/Users/luo/miniconda3/envs/venv-pyrsimg/lib/python3.9/site-packages/nbclient/client.py", line 801, in _async_handle_timeout
    raise CellTimeoutError.error_from_timeout_and_cell(
nbclient.exceptions.CellTimeoutError: A cell timed out while it was being executed, after 30 seconds.
The message was: Cell execution timed out.
Here is a preview of the cell contents:
-------------------
import os
from pyrsimg import readTiff
from pyrsimg import imgShow, imsShow
from pyrsimg import img2patch
from pyrsimg import crop2size, crop2extent
import matplotlib.pyplot as plt
import numpy as np

-------------------

