Traceback (most recent call last):
  File "/Users/luo/miniconda3/envs/venv/lib/python3.11/site-packages/jupyter_cache/executors/utils.py", line 58, in single_nb_execution
    executenb(
  File "/Users/luo/miniconda3/envs/venv/lib/python3.11/site-packages/nbclient/client.py", line 1305, in execute
    return NotebookClient(nb=nb, resources=resources, km=km, **kwargs).execute()
           ^^^^^^^^^^^^^^^^^^^^^^^^^^^^^^^^^^^^^^^^^^^^^^^^^^^^^^^^^^^^^^^^^^^^^
  File "/Users/luo/miniconda3/envs/venv/lib/python3.11/site-packages/jupyter_core/utils/__init__.py", line 158, in wrapped
    return _runner_map[name].run(inner)
           ^^^^^^^^^^^^^^^^^^^^^^^^^^^^
  File "/Users/luo/miniconda3/envs/venv/lib/python3.11/site-packages/jupyter_core/utils/__init__.py", line 125, in run
    return fut.result(None)
           ^^^^^^^^^^^^^^^^
  File "/Users/luo/miniconda3/envs/venv/lib/python3.11/concurrent/futures/_base.py", line 456, in result
    return self.__get_result()
           ^^^^^^^^^^^^^^^^^^^
  File "/Users/luo/miniconda3/envs/venv/lib/python3.11/concurrent/futures/_base.py", line 401, in __get_result
    raise self._exception
  File "/Users/luo/miniconda3/envs/venv/lib/python3.11/site-packages/nbclient/client.py", line 705, in async_execute
    await self.async_execute_cell(
  File "/Users/luo/miniconda3/envs/venv/lib/python3.11/site-packages/nbclient/client.py", line 1058, in async_execute_cell
    await self._check_raise_for_error(cell, cell_index, exec_reply)
  File "/Users/luo/miniconda3/envs/venv/lib/python3.11/site-packages/nbclient/client.py", line 914, in _check_raise_for_error
    raise CellExecutionError.from_cell_and_msg(cell, exec_reply_content)
nbclient.exceptions.CellExecutionError: An error occurred while executing the following cell:
------------------

l8_img = readTiff(path_rsimg)
vars(l8_img).keys()

------------------

----- stderr -----
ERROR 4: docs/source/examples/data/l8_scene_05.tif: No such file or directory
------------------

[0;31m---------------------------------------------------------------------------[0m
[0;31mAttributeError[0m                            Traceback (most recent call last)
Cell [0;32mIn[3], line 1[0m
[0;32m----> 1[0m l8_img [38;5;241m=[39m [43mreadTiff[49m[43m([49m[43mpath_rsimg[49m[43m)[49m
[1;32m      2[0m [38;5;28mvars[39m(l8_img)[38;5;241m.[39mkeys()

File [0;32m~/miniconda3/envs/venv/lib/python3.11/site-packages/pyrsimg-1.0.0-py3.11.egg/pyrsimg/rsimg_io.py:23[0m, in [0;36mreadTiff.__init__[0;34m(self, path_in)[0m
[1;32m     21[0m [38;5;28;01mdef[39;00m [38;5;21m__init__[39m([38;5;28mself[39m, path_in):
[1;32m     22[0m     RS_Data[38;5;241m=[39mgdal[38;5;241m.[39mOpen(path_in)
[0;32m---> 23[0m     [38;5;28mself[39m[38;5;241m.[39mgeotrans [38;5;241m=[39m [43mRS_Data[49m[38;5;241;43m.[39;49m[43mGetGeoTransform[49m()  [38;5;66;03m# [39;00m
[1;32m     24[0m     [38;5;28mself[39m[38;5;241m.[39mrow [38;5;241m=[39m RS_Data[38;5;241m.[39mRasterYSize
[1;32m     25[0m     [38;5;28mself[39m[38;5;241m.[39mcol [38;5;241m=[39m RS_Data[38;5;241m.[39mRasterXSize  [38;5;66;03m# [39;00m

[0;31mAttributeError[0m: 'NoneType' object has no attribute 'GetGeoTransform'

